#VRML_SIM R2025a utf8
# license: Apache License 2.0
# license url: http://www.apache.org/licenses/LICENSE-2.0
# This is a proto file for Webots for the MyCobot280Pi
# Extracted from: /home/lucas/projects/mycobot_ros2/mycobot_description/urdf/mycobot_280_pi/mycobot_280_pi.urdf

PROTO MyCobot280Pi [
  field SFVec3f     translation     0 0 0
  field SFRotation  rotation        0 0 1 0
  field SFString    name            "MyCobot280Pi"  
  field SFString    controller      "basic_control"          
  field MFString    controllerArgs  []              
  field SFString    customData      ""              
  field SFBool      supervisor      FALSE           
  field SFBool      synchronization TRUE
  field SFBool      selfCollision   FALSE          
]
{
  Robot {
    translation    IS translation
    rotation       IS rotation
    controller     IS controller
    controllerArgs IS controllerArgs
    customData     IS customData
    supervisor     IS supervisor
    synchronization IS synchronization
    selfCollision  IS selfCollision

    children [
      #–– Base pose
      Pose {
        translation 0 0 -0.03
        rotation    0 0 1 1.5708
        children [
          DEF G_base_visual CadShape {
            url "/home/lucas/projects/mycobot_ros2/mycobot_description/urdf/mycobot_280_pi/G_base.dae"
          }
        ]  # ← cierre children de Base pose
      }

      #–– Joint1 + hinge to joint2
      Solid {
        children [
          DEF joint1_pi_visual CadShape {
            url "/home/lucas/projects/mycobot_ros2/mycobot_description/urdf/mycobot_280_pi/joint1_pi.dae"
          }
          HingeJoint {
            jointParameters HingeJointParameters {
              axis   0 0 1
              anchor 0 0 0.13956
            }
            device [
              RotationalMotor {
                name       "joint2_to_joint1"
                minPosition -2.9322
                maxPosition  2.9322
                maxTorque    1000
              }
              PositionSensor {
                name "joint2_to_joint1_sensor"
              }
            ]
            endPoint Solid {
              translation 0 0 0.13956
              children [
                #–– Joint2 visual + hinge to joint3
                Pose {
                  translation 0 0 -0.06096
                  rotation    0 0 -1 1.5708
                  children [
                    DEF joint2_visual CadShape {
                      url "/home/lucas/projects/mycobot_ros2/mycobot_description/urdf/mycobot_280_pi/joint2.dae"
                    }
                  ]  # ← cierre children de Joint2 visual
                }
                HingeJoint {
                  jointParameters HingeJointParameters {
                    axis   -0.000004 -1  -0.000004
                    anchor 0         0  -0.001
                  }
                  device [
                    RotationalMotor {
                      name       "joint3_to_joint2"
                      minPosition -2.3562
                      maxPosition  2.3562
                      maxTorque    1000
                    }
                    PositionSensor {
                      name "joint3_to_joint2_sensor"
                    }
                  ]
                  endPoint Solid {
                    translation 0 0 -0.001
                    rotation    0.57735 0.57735 -0.57735 2.0944
                    children [
                      #–– Joint3 visual + hinge to joint4
                      Pose {
                        translation 0 0 0.03256
                        rotation    0 -1 0 1.5708
                        children [
                          DEF joint3_visual CadShape {
                            url "/home/lucas/projects/mycobot_ros2/mycobot_description/urdf/mycobot_280_pi/joint3.dae"
                          }
                        ]  # ← cierre children de Joint3 visual
                      }
                      HingeJoint {
                        jointParameters HingeJointParameters {
                          axis   0 0 1
                          anchor -0.1104 0 0
                        }
                        device [
                          RotationalMotor {
                            name       "joint4_to_joint3"
                            minPosition -2.618
                            maxPosition  2.618
                            maxTorque    1000
                          }
                          PositionSensor {
                            name "joint4_to_joint3_sensor"
                          }
                        ]
                        endPoint Solid {
                          translation -0.1104 0 0
                          children [
                            #–– Joint4 visual + hinge to joint5
                            Pose {
                              translation 0 0 0.03056
                              rotation    0 -1 0 1.5708
                              children [
                                DEF joint4_visual CadShape {
                                  url "/home/lucas/projects/mycobot_ros2/mycobot_description/urdf/mycobot_280_pi/joint4.dae"
                                }
                              ]  # ← cierre children de Joint4 visual
                            }
                            HingeJoint {
                              jointParameters HingeJointParameters {
                                axis   0 0 1
                                anchor -0.096 0 0.06462
                              }
                              device [
                                RotationalMotor {
                                  name       "joint5_to_joint4"
                                  minPosition -2.5307
                                  maxPosition  2.5307
                                  maxTorque    1000
                                }
                                PositionSensor {
                                  name "joint5_to_joint4_sensor"
                                }
                              ]
                              endPoint Solid {
                                translation -0.096 0 0.06462
                                rotation    0 0 -1 1.5708
                                children [
                                  #–– Joint5 visual + hinge to joint6
                                  Pose {
                                    translation 0 -0.001 -0.0345
                                    rotation    0.57735 -0.57735 0.57735 2.0944
                                    children [
                                      DEF joint5_visual CadShape {
                                        url "/home/lucas/projects/mycobot_ros2/mycobot_description/urdf/mycobot_280_pi/joint5.dae"
                                      }
                                    ]  # ← cierre children de Joint5 visual
                                  }
                                  HingeJoint {
                                    jointParameters HingeJointParameters {
                                      axis   0.000004 -1 0
                                      anchor 0       -0.07318 -0.001
                                    }
                                    device [
                                      RotationalMotor {
                                        name       "joint6_to_joint5"
                                        minPosition -2.8798
                                        maxPosition  2.8798
                                        maxTorque    1000
                                      }
                                      PositionSensor {
                                        name "joint6_to_joint5_sensor"
                                      }
                                    ]
                                    endPoint Solid {
                                      translation 0 -0.07318 -0.001
                                      rotation    0.57735 -0.57735 0.57735 2.0944
                                      children [
                                        #–– Joint6 visual + hinge to flange
                                        Pose {
                                          translation 0 0 -0.038
                                          children [
                                            DEF joint6_visual CadShape {
                                              url "/home/lucas/projects/mycobot_ros2/mycobot_description/urdf/mycobot_280_pi/joint6.dae"
                                            }
                                          ]  # ← cierre children de Joint6 visual
                                        }
                                        HingeJoint {
                                          jointParameters HingeJointParameters {
                                            axis   0 1 0
                                            anchor 0 0.0456 0
                                          }
                                          device [
                                            RotationalMotor {
                                              name       "joint6output_to_joint6"
                                              minPosition -3.1416
                                              maxPosition  3.1416
                                              maxTorque    1000
                                            }
                                            PositionSensor {
                                              name "joint6output_to_joint6_sensor"
                                            }
                                          ]
                                          endPoint Solid {
                                            translation 0 0.0456 0
                                            rotation    -1 0 0 1.5708
                                            children [
                                              #–– Flange visual
                                              Pose {
                                                translation 0 0 -0.012
                                                children [
                                                  DEF joint7_visual CadShape {
                                                    url "/home/lucas/projects/mycobot_ros2/mycobot_description/urdf/mycobot_280_pi/joint7.dae"
                                                  }
                                                ]  # ← cierre children de Flange visual
                                              }
                                            ]  # ← cierre children de Flange
                                            name "joint6_flange"
                                            boundingObject Pose {
                                              translation 0 0 -0.012
                                              children [
                                                DEF joint7 Mesh {
                                                  url "/home/lucas/projects/mycobot_ros2/mycobot_description/urdf/mycobot_280_pi/joint7.dae"
                                                }
                                              ]  # ← cierre children de boundingObject de Flange
                                            }
                                            physics Physics {
                                              mass 0.05
                                            }
                                          }  # ← cierre endPoint de Flange
                                        }  # ← cierre HingeJoint de Flange
                                      ]  # ← cierre children de Joint6
                                      name "joint6"
                                      boundingObject Pose {
                                        translation 0 0 -0.038
                                        children [
                                          DEF joint6 Mesh {
                                            url "/home/lucas/projects/mycobot_ros2/mycobot_description/urdf/mycobot_280_pi/joint6.dae"
                                          }
                                        ]  # ← cierre children de boundingObject de Joint6
                                      }
                                      physics Physics {
                                        mass 0.05
                                      }
                                    }  # ← cierre endPoint de Joint6
                                  }  # ← cierre HingeJoint de Joint6
                                ]  # ← cierre children de Joint5
                                name "joint5"
                                boundingObject Pose {
                                  translation 0 -0.001 -0.0345
                                  children [
                                    DEF joint5 Mesh {
                                      url "/home/lucas/projects/mycobot_ros2/mycobot_description/urdf/mycobot_280_pi/joint5.dae"
                                    }
                                  ]  # ← cierre children de boundingObject de Joint5
                                }
                                physics Physics {
                                  mass 0.05
                                }
                              }  # ← cierre endPoint de Joint5
                            }  # ← cierre HingeJoint de Joint5
                          ]  # ← cierre children de Joint4
                          name "joint4"
                          boundingObject Pose {
                            translation 0 0 0.03056
                            children [
                              DEF joint4 Mesh {
                                url "/home/lucas/projects/mycobot_ros2/mycobot_description/urdf/mycobot_280_pi/joint4.dae"
                              }
                            ]  # ← cierre children de boundingObject de Joint4
                          }
                          physics Physics {
                            mass 0.05
                          }
                        }  # ← cierre endPoint de Joint4
                      }  # ← cierre HingeJoint de Joint4
                    ]  # ← cierre children de Joint3
                    name "joint3"
                    boundingObject Pose {
                      translation 0 0 0.03256
                      children [
                        DEF joint3 Mesh {
                          url "/home/lucas/projects/mycobot_ros2/mycobot_description/urdf/mycobot_280_pi/joint3.dae"
                        }
                      ]  # ← cierre children de boundingObject de Joint3
                    }
                    physics Physics {
                      mass 0.05
                    }
                  }  # ← cierre endPoint de Joint3
                }  # ← cierre HingeJoint de Joint3
              ]  # ← cierre children de Joint2
              name "joint2"
              boundingObject Pose {
                translation 0 0 -0.06096
                children [
                  DEF joint2 Mesh {
                    url "/home/lucas/projects/mycobot_ros2/mycobot_description/urdf/mycobot_280_pi/joint2.dae"
                  }
                ]  # ← cierre children de boundingObject de Joint2
              }
              physics Physics {
                mass 0.05
              }
            }  # ← cierre endPoint de Joint2
          }  # ← cierre HingeJoint de Joint2
        ]  # ← cierre children de Joint1
        name "joint1"
        boundingObject DEF joint1_pi Mesh {
          url "/home/lucas/projects/mycobot_ros2/mycobot_description/urdf/mycobot_280_pi/joint1_pi.dae"
        }
        physics Physics {
          mass 0.05
        }
      }
      Connector {
        translation 0 0 0
        rotation    0 0 1 0
        name   "flange_connector"
        type   "active"
        model  "AdaptiveGripper"
        snap   TRUE
      }
    ]  # ← cierre children del Robot
    name IS name
    boundingObject Pose {
      translation 0 0 -0.03
      rotation    0 0 1 1.5708
      children [
        DEF G_base Mesh {
          url "/home/lucas/projects/mycobot_ros2/mycobot_description/urdf/mycobot_280_pi/G_base.dae"
        }
      ]  # ← cierre children de boundingObject del Robot
    }
  }  # ← cierre Robot
}  # ← cierre PROTO MyCobot280Pi